<?xml version="1.0"?>
<robot name="hexarotor">


  <link name="mainbody">
    <visual>
      <geometry>
        <cylinder radius=".071" length=".02"/>
        <origin rpy="0 0 0" xyz="0.0 0.0 0.01"/>
      </geometry>
<!--       <geometry>
        <box size="0.2 0.01 0.01"/>
        <origin rpy="0 0 0" xyz="0.10 0.0 0.0"/>
      </geometry> -->
      <material name="blue">
        <color rgba="0 0 .8 1"/>
      </material>
    </visual>
    <collision>
      <geometry>
          <cylinder radius=".07" length=".02"/>
      </geometry>
      <origin xyz="0.0 0.0 0.0"/>
    </collision>
    <inertial>
      <mass value="0.1"/>
      <inertia ixx="1.0" ixy="0.0" ixz="0.0" iyy="1.0" iyz="0.0" izz="1.0"/>
    </inertial>
  </link>

<link name="prop1">
    <visual>
      <geometry>
        <cylinder radius=".062" length=".002"/>
        <origin rpy="0 0 0" xyz="0.0 0.0 0.0"/>
      </geometry>
      <material name="green">
        <color rgba="0 1 0 0.4"/>
      </material>
    </visual>
    <inertial>
    <origin xyz="0.0 0.0 0.001"/>
      <mass value="0.003"/>
      <inertia ixx="1.0" ixy="0.0" ixz="0.0" iyy="1.0" iyz="0.0" izz="1.0"/>
    </inertial>
     <collision>
      <geometry>
        <cylinder radius=".062" length=".002"/>
      </geometry>
      <origin rpy="0 0 0" xyz="0.0 0.0 0.001"/>
    </collision>
  </link>

<link name="prop2">
    <visual>
      <geometry>
        <cylinder radius=".062" length=".002"/>
        <origin rpy="0 0 0" xyz="0.0 0.0 0.0"/>
      </geometry>
      <material name="green">
        <color rgba="0 1 0 0.4"/>
      </material>
    </visual>
    <inertial>
    <origin xyz="0.0 0.0 0.001"/>
      <mass value="0.003"/>
      <inertia ixx="1.0" ixy="0.0" ixz="0.0" iyy="1.0" iyz="0.0" izz="1.0"/>
    </inertial>
     <collision>
      <geometry>
        <cylinder radius=".062" length=".002"/>
      </geometry>
      <origin rpy="0 0 0" xyz="0.0 0.0 0.001"/>
    </collision>
  </link>

<link name="prop3">
    <visual>
      <geometry>
        <cylinder radius=".062" length=".002"/>
        <origin rpy="0 0 0" xyz="0.0 0.0 0.0"/>
      </geometry>
      <material name="green">
        <color rgba="0 1 0 0.4"/>
      </material>
    </visual>
    <inertial>
    <origin xyz="0.0 0.0 0.001"/>
      <mass value="0.003"/>
      <inertia ixx="1.0" ixy="0.0" ixz="0.0" iyy="1.0" iyz="0.0" izz="1.0"/>
    </inertial>
     <collision>
      <geometry>
        <cylinder radius=".062" length=".002"/>
      </geometry>
      <origin rpy="0 0 0" xyz="0.0 0.0 0.001"/>
    </collision>
  </link>

<link name="prop4">
    <visual>
      <geometry>
        <cylinder radius=".062" length=".002"/>
        <origin rpy="0 0 0" xyz="0.0 0.0 0.0"/>
      </geometry>
      <material name="green">
        <color rgba="0 1 0 0.4"/>
      </material>
    </visual>
    <inertial>
    <origin xyz="0.0 0.0 0.001"/>
      <mass value="0.003"/>
      <inertia ixx="1.0" ixy="0.0" ixz="0.0" iyy="1.0" iyz="0.0" izz="1.0"/>
    </inertial>
     <collision>
      <geometry>
        <cylinder radius=".062" length=".002"/>
      </geometry>
      <origin rpy="0 0 0" xyz="0.0 0.0 0.001"/>
    </collision>
  </link>

<link name="prop5">
    <visual>
      <geometry>
        <cylinder radius=".062" length=".002"/>
        <origin rpy="0 0 0" xyz="0.0 0.0 0.0"/>
      </geometry>
      <material name="green">
        <color rgba="0 1 0 0.4"/>
      </material>
    </visual>
    <inertial>
    <origin xyz="0.0 0.0 0.001"/>
      <mass value="0.003"/>
      <inertia ixx="1.0" ixy="0.0" ixz="0.0" iyy="1.0" iyz="0.0" izz="1.0"/>
    </inertial>
     <collision>
      <geometry>
        <cylinder radius=".062" length=".002"/>
      </geometry>
      <origin rpy="0 0 0" xyz="0.0 0.0 0.001"/>
    </collision>
  </link>

<link name="prop6">
    <visual>
      <geometry>
        <cylinder radius=".062" length=".002"/>
        <origin rpy="0 0 0" xyz="0.0 0.0 0.0"/>
      </geometry>
      <material name="green">
        <color rgba="0 1 0 0.4"/>
      </material>
    </visual>
    <inertial>
    <origin xyz="0.0 0.0 0.001"/>
      <mass value="0.003"/>
      <inertia ixx="1.0" ixy="0.0" ixz="0.0" iyy="1.0" iyz="0.0" izz="1.0"/>
    </inertial>
     <collision>
      <geometry>
        <cylinder radius=".062" length=".002"/>
      </geometry>
      <origin rpy="0 0 0" xyz="0.0 0.0 0.001"/>
    </collision>
  </link>

  <link name="landinggear">
    <visual>
      <geometry>
        <box size="0.06 0.06 0.06"/>
        <origin rpy="0 0 0" xyz="0.0 0.0 0.0"/>
      </geometry>
      <material name="blue">
        <color rgba="0 0 .8 1"/>
      </material>
    </visual>
    <collision>
      <geometry>
          <box size="0.06 0.06 0.06"/>
      </geometry>
      <origin xyz="0.0 0.0 0.0"/>
    </collision>
    <inertial>
      <mass value="0.1"/>
      <inertia ixx="1.0" ixy="0.0" ixz="0.0" iyy="1.0" iyz="0.0" izz="1.0"/>
    </inertial>
  </link>

<link name="arm1">
    <visual>
      <geometry>
        <box size="0.08 0.02 0.02"/> 
      </geometry>
      <origin rpy="0 0 0" xyz="0.04 0.0 0.0"/>
      <material name="white">
        <color rgba="1 1 1 1"/>
      </material>
    </visual>
    <inertial>
    <origin xyz="0.04 0.01 0.01"/>
      <mass value="0.03"/>
      <inertia ixx="1.0" ixy="0.0" ixz="0.0" iyy="1.0" iyz="0.0" izz="1.0"/>
    </inertial>
     <collision>
      <geometry>
        <box size="0.08 0.02 0.02"/> 
      </geometry>
      <origin rpy="0 0 0" xyz="0.04 0.01 0.01"/>
    </collision>
  </link>

<link name="arm2">
    <visual>
      <geometry>
        <box size="0.08 0.02 0.02"/> 
      </geometry>
      <origin rpy="0 0 0" xyz="0.04 0.0 0.0"/>
      <material name="white">
        <color rgba="1 1 1 1"/>
      </material>
    </visual>
    <inertial>
    <origin xyz="0.04 0.01 0.01"/>
      <mass value="0.03"/>
      <inertia ixx="1.0" ixy="0.0" ixz="0.0" iyy="1.0" iyz="0.0" izz="1.0"/>
    </inertial>
     <collision>
      <geometry>
        <box size="0.08 0.02 0.02"/> 
      </geometry>
      <origin rpy="0 0 0" xyz="0.04 0.01 0.01"/>
    </collision>
  </link>

  <link name="arm3">
    <visual>
      <geometry>
        <box size="0.08 0.02 0.02"/> 
      </geometry>
      <origin rpy="0 0 0" xyz="0.04 0.0 0.0"/>
      <material name="white">
        <color rgba="1 1 1 1"/>
      </material>
    </visual>
    <inertial>
    <origin xyz="0.04 0.01 0.01"/>
      <mass value="0.03"/>
      <inertia ixx="1.0" ixy="0.0" ixz="0.0" iyy="1.0" iyz="0.0" izz="1.0"/>
    </inertial>
     <collision>
      <geometry>
        <box size="0.08 0.02 0.02"/> 
      </geometry>
      <origin rpy="0 0 0" xyz="0.04 0.01 0.01"/>
    </collision>
  </link>

    <link name="arm4">
     <visual>
      <geometry>
        <box size="0.08 0.02 0.02"/> 
      </geometry>
      <origin rpy="0 0 0" xyz="0.04 0.0 0.0"/>
      <material name="white">
        <color rgba="1 1 1 1"/>
      </material>
    </visual>
    <inertial>
    <origin xyz="0.04 0.01 0.01"/>
      <mass value="0.03"/>
      <inertia ixx="1.0" ixy="0.0" ixz="0.0" iyy="1.0" iyz="0.0" izz="1.0"/>
    </inertial>
     <collision>
      <geometry>
        <box size="0.08 0.02 0.02"/> 
      </geometry>
      <origin rpy="0 0 0" xyz="0.04 0.01 0.01"/>
    </collision>
  </link>

    <link name="arm5">
     <visual>
      <geometry>
        <box size="0.08 0.02 0.02"/> 
      </geometry>
      <origin rpy="0 0 0" xyz="0.04 0.0 0.0"/>
      <material name="white">
        <color rgba="1 1 1 1"/>
      </material>
    </visual>
    <inertial>
    <origin xyz="0.04 0.01 0.01"/>
      <mass value="0.03"/>
      <inertia ixx="1.0" ixy="0.0" ixz="0.0" iyy="1.0" iyz="0.0" izz="1.0"/>
    </inertial>
     <collision>
      <geometry>
        <box size="0.08 0.02 0.02"/> 
      </geometry>
      <origin rpy="0 0 0" xyz="0.048 0.01 0.01"/>
    </collision>
  </link>

    <link name="arm6">
    <visual>
      <geometry>
        <box size="0.08 0.02 0.02"/> 
      </geometry>
      <origin rpy="0 0 0" xyz="0.04 0.0 0.0"/>
      <material name="white">
        <color rgba="1 1 1 1"/>
      </material>
    </visual>
    <inertial>
    <origin xyz="0.04 0.01 0.01"/>
      <mass value="0.03"/>
      <inertia ixx="1.0" ixy="0.0" ixz="0.0" iyy="1.0" iyz="0.0" izz="1.0"/>
    </inertial>
     <collision>
      <geometry>
        <box size="0.08 0.02 0.02"/> 
      </geometry>
      <origin rpy="0 0 0" xyz="0.045 0.01 0.01"/>
    </collision>
  </link>

  <joint name="body_to_arm1" type="revolute">
    <axis xyz="0 0 1"/>
    <origin rpy="0 0 -0.523" xyz="0.061 -0.035 0"/>
    <parent link="mainbody"/>
    <child link="arm1"/>
    <limit effort="1" velocity="0.5"/>
    <joint_properties damping="0.0" friction="0.0"/>
  </joint>

    <joint name="body_to_arm2" type="revolute">
    <axis xyz="0 0 1"/>
    <origin rpy="0 0 -1.57" xyz="0.0 -0.07 0"/>
    <parent link="mainbody"/>
    <child link="arm2"/>
    <limit effort="1" velocity="0.5"/>
    <joint_properties damping="0.0" friction="0.0"/>
  </joint>

    <joint name="body_to_arm3" type="revolute">
    <axis xyz="0 0 1"/>
    <origin rpy="0 0 -2.617" xyz="-0.061 -0.035 0"/>
    <parent link="mainbody"/>
    <child link="arm3"/>
    <limit effort="1" velocity="0.5"/>
    <joint_properties damping="0.0" friction="0.0"/>
  </joint>

  <joint name="body_to_arm4" type="revolute">
    <axis xyz="0 0 1"/>
    <origin rpy="0 0 2.617" xyz="-0.061 0.035 0"/>
    <parent link="mainbody"/>
    <child link="arm4"/>
    <limit effort="1" velocity="0.5"/>
    <joint_properties damping="0.0" friction="0.0"/>
  </joint>

    <joint name="body_to_arm5" type="revolute">
    <axis xyz="0 0 1"/>
    <origin rpy="0 0 1.57" xyz="0.0 0.07 0"/>
    <parent link="mainbody"/>
    <child link="arm5"/>
    <limit effort="1" velocity="0.5"/>
    <joint_properties damping="0.0" friction="0.0"/>
  </joint>

    <joint name="body_to_arm6" type="revolute">
    <axis xyz="0 0 1"/>
    <origin rpy="0 0 .523" xyz="0.061 0.035 0"/>
    <parent link="mainbody"/>
    <child link="arm6"/>
    <limit effort="1" velocity="0.5"/>
    <joint_properties damping="0.0" friction="0.0"/>
  </joint>

  <joint name="body_to_landinggear" type="fixed">
    <origin rpy="0 0 0" xyz="0.0 0.0 -0.05"/>
    <parent link="mainbody"/>
    <child link="landinggear"/>
  </joint>

  <joint name="arm1_to_prop1" type="fixed">
    <origin rpy="0 0 0" xyz="0.06 0.0 0.02"/>
    <parent link="arm1"/>
    <child link="prop1"/>
  </joint>

    <joint name="arm2_to_prop2" type="fixed">
    <origin rpy="0 0 0" xyz="0.06 0.0 -0.02"/>
    <parent link="arm2"/>
    <child link="prop2"/>
  </joint>

  <joint name="arm3_to_prop3" type="fixed">
    <origin rpy="0 0 0" xyz="0.06 0.0 0.02"/>
    <parent link="arm3"/>
    <child link="prop3"/>
  </joint>

  <joint name="arm4_to_prop4" type="fixed">
    <origin rpy="0 0 0" xyz="0.06 0.0 -0.02"/>
    <parent link="arm4"/>
    <child link="prop4"/>
  </joint>

  <joint name="arm5_to_prop5" type="fixed">
    <origin rpy="0 0 0" xyz="0.06 0.0 0.02"/>
    <parent link="arm5"/>
    <child link="prop5"/>
  </joint>

  <joint name="arm6_to_prop6" type="fixed">
    <origin rpy="0 0 0" xyz="0.06 0.0 -0.02"/>
    <parent link="arm6"/>
    <child link="prop6"/>
  </joint>


</robot>